Workbook

Sheet 1 - Infos Générales
A1: PIÈCES ANNEXES À LA DÉCLARATION FISCALE
A2: IMPÔTS SUR LES SOCIÉTÉS — Modèle Comptable Normal
A3: Champ | B3: Valeur
A4: Raison sociale
A5: Taxe professionnelle
A6: Identifiant fiscal
A7: Adresse
A8: Exercice
A9: Date de déclaration

Sheet 2 - Bilan Actif
A1: Tableau N°01 | B1: Bilan (ACTIF) | C1: Identifiant fiscal: | D1: ='1 - Infos Générales'!B6
A2: ='1 - Infos Générales'!B4 | C2: Exercice | D2: ='1 - Infos Générales'!B8
C3: EXERCICE | F3: EXERCICE PRECEDENT
B4: ACTIF | C4: BRUT | D4: AMORT. & PROV. | E4: NET | F4: NET (N-1)
A5: ▶ ACTIF IMMOBILISÉ | B5: Immobilisations en non-valeurs [A] | C5: =C6+C7+C8 | D5: =D6+D7+D8 | E5: =C5-D5 | F5: =F6+F7+F8
B6: Frais préliminaires | E6: =C6-D6
B7: Charges à répartir sur plusieurs exercices | E7: =C7-D7
B8: Primes de remboursement des obligations | E8: =C8-D8
B9: Immobilisations incorporelles [B] | C9: =C10+C11+C12+C13 | D9: =D10+D11+D12+D13 | E9: =C9-D9 | F9: =F10+F11+F12+F13
B10: Immobilisations en Recherche et Développement | E10: =C10-D10
B11: Brevets, marques, droits et valeurs similaires | E11: =C11-D11
B12: Fonds commercial | E12: =C12-D12
B13: Autres immobilisations incorporelles | E13: =C13-D13
B14: Immobilisations corporelles [C] | C14: =C15+C16+C17+C18+C19+C20+C21 | D14: =D15+D16+D17+D18+D19+D20+D21 | E14: =C14-D14 | F14: =F15+F16+F17+F18+F19+F20+F21
B15: Terrains | E15: =C15-D15
B16: Constructions | E16: =C16-D16
B17: Installations techniques, matériel et outillage | E17: =C17-D17
B18: Matériel de transport | E18: =C18-D18
B19: Mobilier, Mat. de bureau, Aménagements divers | E19: =C19-D19
B20: Autres immobilisations corporelles | E20: =C20-D20
B21: Immobilisations corporelles en cours | E21: =C21-D21
B22: Immobilisations financières [D] | C22: =C23+C24+C25+C26 | D22: =D23+D24+D25+D26 | E22: =C22-D22 | F22: =F23+F24+F25+F26
B23: Prêts immobilisés | E23: =C23-D23
B24: Autres créances financières | E24: =C24-D24
B25: Titres de participation | E25: =C25-D25
B26: Autres titres immobilisés | E26: =C26-D26
B27: Écarts de conversion actif [E] | C27: 0 | D27: 0 | E27: =C27-D27 | F27: 0
B28: Diminution des créances immobilisées | C28: 0 | D28: 0 | E28: =C28-D28 | F28: 0
B29: Augmentation des dettes financières | C29: 0 | D29: 0 | E29: =C29-D29 | F29: 0
B30: TOTAL I (A+B+C+D+E) | C30: =C5+C9+C14+C22+C27 | D30: =D5+D9+D14+D22+D27 | E30: =E5+E9+E14+E22+E27 | F30: =F5+F9+F14+F22+F27
A31: ▶ ACTIF CIRCULANT | B31: Stocks [F] | C31: =C32+C33+C34+C35+C36 | D31: =D32+D33+D34+D35+D36 | E31: =C31-D31 | F31: =F32+F33+F34+F35+F36
B32: Marchandises | E32: =C32-D32
B33: Matières et fournitures consommables | E33: =C33-D33
B34: Produits en cours | E34: =C34-D34
B35: Produits intermédiaires et produits résiduels | E35: =C35-D35
B36: Produits finis | E36: =C36-D36
B37: Créances de l'actif circulant [G] | C37: =C38+C39+C40+C41+C42+C43+C44 | D37: =D38+D39+D40+D41+D42+D43+D44 | E37: =C37-D37 | F37: =F38+F39+F40+F41+F42+F43+F44
B38: Fournisseurs débiteurs, avances et acomptes | E38: =C38-D38
B39: Clients et comptes rattachés | E39: =C39-D39
B40: Personnel | E40: =C40-D40
...

Sheet 3 - Bilan Passif
A1: Tableau N°02 | B1: BILAN (PASSIF) | C1: Identifiant fiscal: | D1: ='1 - Infos Générales'!B6
A2: ='1 - Infos Générales'!B4 | C2: Exercice | D2: ='1 - Infos Générales'!B8
B3: PASSIF | C3: EXERCICE N | D3: EXERCICE N-1
A4: ▶ FINANCEMENT PERMANENT | B4: ▶ CAPITAUX PROPRES | C4: =C16 | D4: =D16
B5: Capital social ou personnel | C5: =C7 | D5: =D7
B6: Moins:actionnaires, capital souscrit non appelé
B7: capital appelé
B8: dont versé
B9: Prime d'émission, de fusion, d'apport
B10: Écarts de réévaluation
B11: Réserve légale
B12: Autres réserves
B13: Report à nouveau
B14: Résultat en instance d'affectation
B15: Résultat net de l'exercice
B16: Total des capitaux propres (A) | C16: =C15+C13+C12+C11+C10+C9+C5 | D16: =D15+D13+D12+D11+D10+D9+D5
B17: ▶ Capitaux propres assimilés (B) | C17: =C18+C19 | D17: =D18+D19
B18: Subventions d'investissement
B19: Provisions réglementées
B20: Dettes de financement (C)
B21: Emprunts obligataires
B22: Autres dettes de financement
B23: Provisions durables pour risques et charges (D)
B24: Provisions pour risques
B25: Provisions pour charges
B26: Écarts de conversion - passif (E)
B27: Augmentation des créances immobilisées
B28: Diminution des dettes de financement
B29: TOTAL I (A+B+C+D+E) PASSIF | C29: =C16+C17+C20+C23+C26 | D29: =D16+D17+D20+D23+D26
A30: ▶ PASSIF CIRCULANT | B30: ▶ Dettes du passif circulant (F) | C30: =C41 | D30: =D41
B31: Fournisseurs et comptes rattachés
B32: Clients créditeurs, avances et acomptes
B33: Personnel
B34: Organismes sociaux
B35: État
B36: Comptes d'associés
B37: Autres créanciers
B38: Comptes de régularisation passif
B39: Autres provisions pour risques et charges (G)
B40: Écarts de conversion - passif éléments circulants (H)
...

Sheet 4 - CPC
B1: Tableau N°02 | C1: CPC (Hors taxes) | D1: Identifiant fiscal: | E1: ='1 - Infos Générales'!B6
B2: ='1 - Infos Générales'!B4 | D2: Exercice | E2: ='1 - Infos Générales'!B8
B3: DÉSIGNATION | C3: OPERATIONS | E3: TOTAL N | F3: TOTAL N-1
C4: Propres à l'exercice N | D4: Exercices précédents
A5: EXPLOITATION FINANCIER NON COURANT | B5: ▶ PRODUITS D'EXPLOITATION
B6: Ventes de marchandises (en l'état) | E6: =C6+D6
B7: Ventes de biens et services produits | E7: =C7+D7
B8: Chiffre d'affaires | C8: =C7+C6 | D8: =D7+D6 | E8: =E7+E6 | F8: =F7+F6
B9: Variation de stocks de produits | E9: =C9+D9
B10: Immobilisations produites par l'entreprise | E10: =C10+D10
B11: Subventions d'exploitation | E11: =C11+D11
B12: Autres produits d'exploitation | E12: =C12+D12
B13: Reprises d'exploitation : transferts de charges | E13: =C13+D13
B14: TOTAL I - PRODUITS D'EXPLOITATION | C14: =C13+C12+C11+C10+C9+C8 | D14: =D13+D12+D11+D10+D9+D8 | E14: =E13+E12+E11+E10+E9+E8 | F14: =F13+F12+F11+F10+F9+F8
B15: ▶ CHARGES D'EXPLOITATION
B16: Achats revendus de marchandises | E16: =C16+D16
B17: Achats consommés de matières et fournitures | E17: =C17+D17
B18: Autres charges externes | E18: =C18+D18
B19: Impôts et taxes | E19: =C19+D19
B20: Charges de personnel | E20: =C20+D20
B21: Autres charges d'exploitation | E21: =C21+D21
B22: Dotations d'exploitation | E22: =C22+D22
B23: TOTAL II - CHARGES D'EXPLOITATION | C23: =C16+C17+C18+C19+C20+C21+C22 | D23: =D16+D17+D18+D19+D20+D21+D22 | E23: =E16+E17+E18+E19+E20+E21+E22 | F23: =F16+F17+F18+F19+F20+F21+F22
B24: RÉSULTAT D'EXPLOITATION (I-II) | C24: =C14-C23 | D24: =D14-D23 | E24: =E14-E23 | F24: =F14-F23
B25: ▶ PRODUITS FINANCIERS
B26: Produits des titres de participation | E26: =C26+D26
B27: Gains de change | E27: =C27+D27
B28: Intérêts et autres produits financiers | E28: =C28+D28
B29: Reprises financières : transferts de charges | E29: =C29+D29
B30: TOTAL IV - PRODUITS FINANCIERS | C30: =C26+C27+C28+C29 | D30: =D26+D27+D28+D29 | E30: =E26+E27+E28+E29 | F30: =F26+F27+F28+F29
B31: ▶ CHARGES FINANCIÈRES
B32: Charges d'intérêts | E32: =C32+D32
B33: Pertes de change | E33: =C33+D33
B34: Autres charges financières | E34: =C34+D34
B35: Dotations financières | E35: =C35+D35
B36: TOTAL V - CHARGES FINANCIÈRES | C36: =C32+C33+C34+C35 | D36: =D32+D33+D34+D35 | E36: =E32+E33+E34+E35 | F36: =F32+F33+F34+F35
B37: RÉSULTAT FINANCIER (IV-V) | C37: =C30-C36 | D37: =D30-D36 | E37: =E30-E36 | F37: =F30-F36
B38: RÉSULTAT COURANT (III+VI) | C38: =C24+C37 | D38: =D24+D37 | E38: =E24+E37 | F38: =F24+F37
B39: ▶ PRODUITS NON COURANTS
B40: Produits des cessions d'immobilisations | E40: =C40+D40
...

Sheet 5 - Tableau de Bord
A1: TABLEAU DE BORD — SYNTHÈSE FINANCIÈRE
A2: AGENCE DU BASSIN HYDRAULIQUE DU SEBOU
A3: INDICATEUR | B3: EXERCICE N | C3: EXERCICE N-1 | D3: Δ (N vs N-1) | E3: Unité
A4: 📈 COMPTE DE RÉSULTATS
A5: Chiffre d'affaires | B5: ='4 - CPC'!E8 | C5: ='4 - CPC'!F8 | D5: =B5-C5 | E5: MAD
A6: Produits d'exploitation | B6: ='4 - CPC'!E14 | C6: ='4 - CPC'!F14 | D6: =B6-C6 | E6: MAD
A7: Charges d'exploitation | B7: ='4 - CPC'!E23 | C7: ='4 - CPC'!F23 | D7: =B7-C7 | E7: MAD
A8: Résultat d'exploitation | B8: ='4 - CPC'!E24 | C8: ='4 - CPC'!F24 | D8: =B8-C8 | E8: MAD
A9: Résultat financier | B9: ='4 - CPC'!E37 | C9: ='4 - CPC'!F37 | D9: =B9-C9 | E9: MAD
A10: Résultat courant | B10: ='4 - CPC'!E38 | C10: ='4 - CPC'!F38 | D10: =B10-C10 | E10: MAD
A11: Résultat net de l'exercice | B11: ='4 - CPC'!E55 | C11: ='4 - CPC'!F55 | D11: =B11-C11 | E11: MAD
A12: 📊 BILAN — ACTIF
A13: Actif immobilisé net | B13: ='2 - Bilan Actif'!E30 | C13: ='2 - Bilan Actif'!F30 | D13: =B13-C13 | E13: MAD
A14: Actif circulant net | B14: ='2 - Bilan Actif'!E47 | C14: ='2 - Bilan Actif'!F47 | D14: =B14-C14 | E14: MAD
A15: Trésorerie actif | B15: ='2 - Bilan Actif'!E51 | C15: ='2 - Bilan Actif'!F51 | D15: =B15-C15 | E15: MAD
A16: TOTAL GÉNÉRAL ACTIF | B16: ='2 - Bilan Actif'!E52 | C16: ='2 - Bilan Actif'!F52 | D16: =B16-C16 | E16: MAD
A17: 📊 BILAN — PASSIF
A18: Capitaux propres | B18: ='3 - Bilan Passif'!C16 | C18: ='3 - Bilan Passif'!D16 | D18: =B18-C18 | E18: MAD
A19: Subventions d'investissement | B19: ='3 - Bilan Passif'!C18 | C19: ='3 - Bilan Passif'!D18 | D19: =B19-C19 | E19: MAD
A20: Financement permanent | B20: ='3 - Bilan Passif'!C29 | C20: ='3 - Bilan Passif'!D29 | D20: =B20-C20 | E20: MAD
A21: TOTAL GÉNÉRAL PASSIF | B21: ='3 - Bilan Passif'!C46 | C21: ='3 - Bilan Passif'!D46 | D21: =B21-C21 | E21: MAD
