Workbook

Sheet 1 - Infos Générales
A1: PIÈCES ANNEXES À LA DÉCLARATION FISCALE
A2: IMPÔTS SUR LES SOCIÉTÉS — Modèle Comptable Normal
A3: Champ | B3: Valeur
A4: Raison sociale
A5: Taxe professionnelle
A6: Identifiant fiscal
A7: Adresse
A8: Exercice
A9: Date de déclaration

Sheet 2 - Bilan Actif
A1: BILAN — ACTIF | Du 01/01/2017 au 31/12/2017
A2: AGENCE DU BASSIN HYDRAULIQUE DU SEBOU — IF: 4510887
A3: ACTIF | B3: BRUT (N) | C3: AMORT. & PROV. | D3: NET (N) | E3: NET (N-1)
A4: ▶ ACTIF IMMOBILISÉ
A5: Immobilisations en non-valeurs [A] | B5: =B6+B7+B8 | C5: =C6+C7+C8 | D5: =B5-C5 | E5: =E6+E7+E8
A6: Frais préliminaires | D6: =B6-C6
A7: Charges à répartir sur plusieurs exercices | D7: =B7-C7
A8: Primes de remboursement des obligations | D8: =B8-C8
A9: Immobilisations incorporelles [B] | B9: =B10+B11+B12+B13 | C9: =C10+C11+C12+C13 | D9: =B9-C9 | E9: =E10+E11+E12+E13
A10: Immobilisations en Recherche et Développement | D10: =B10-C10
A11: Brevets, marques, droits et valeurs similaires | D11: =B11-C11
A12: Fonds commercial | D12: =B12-C12
A13: Autres immobilisations incorporelles | D13: =B13-C13
A14: Immobilisations corporelles [C] | B14: =B15+B16+B17+B18+B19+B20+B21 | C14: =C15+C16+C17+C18+C19+C20+C21 | D14: =B14-C14 | E14: =E15+E16+E17+E18+E19+E20+E21
A15: Terrains | D15: =B15-C15
A16: Constructions | D16: =B16-C16
A17: Installations techniques, matériel et outillage | D17: =B17-C17
A18: Matériel de transport | D18: =B18-C18
A19: Mobilier, Mat. de bureau, Aménagements divers | D19: =B19-C19
A20: Autres immobilisations corporelles | D20: =B20-C20
A21: Immobilisations corporelles en cours | D21: =B21-C21
A22: Immobilisations financières [D] | B22: =B23+B24+B25+B26 | C22: =C23+C24+C25+C26 | D22: =B22-C22 | E22: =E23+E24+E25+E26
A23: Prêts immobilisés | D23: =B23-C23
A24: Autres créances financières | D24: =B24-C24
A25: Titres de participation | D25: =B25-C25
A26: Autres titres immobilisés | D26: =B26-C26
A27: Écarts de conversion actif [E] | B27: 0 | C27: 0 | D27: =B27-C27 | E27: 0
A28: Diminution des créances immobilisées | B28: 0 | C28: 0 | D28: =B28-C28 | E28: 0
A29: Augmentation des dettes financières | B29: 0 | C29: 0 | D29: =B29-C29 | E29: 0
A30: TOTAL I (A+B+C+D+E) | B30: =B5+B9+B14+B22+B27 | C30: =C5+C9+C14+C22+C27 | D30: =D5+D9+D14+D22+D27 | E30: =E5+E9+E14+E22+E27
A31: ▶ ACTIF CIRCULANT
A32: Stocks [F] | B32: =B33+B34+B35+B36+B37 | C32: =C33+C34+C35+C36+C37 | D32: =B32-C32 | E32: =E33+E34+E35+E36+E37
A33: Marchandises | D33: =B33-C33
A34: Matières et fournitures consommables | D34: =B34-C34
A35: Produits en cours | D35: =B35-C35
A36: Produits intermédiaires et produits résiduels | D36: =B36-C36
A37: Produits finis | D37: =B37-C37
A38: Créances de l'actif circulant [G] | B38: =B39+B40+B41+B42+B43+B44+B45 | C38: =C39+C40+C41+C42+C43+C44+C45 | D38: =B38-C38 | E38: =E39+E40+E41+E42+E43+E44+E45
A39: Fournisseurs débiteurs, avances et acomptes | D39: =B39-C39
A40: Clients et comptes rattachés | D40: =B40-C40
...

Sheet 3 - Bilan Passif
A1: BILAN — PASSIF | Du 01/01/2017 au 31/12/2017
A2: AGENCE DU BASSIN HYDRAULIQUE DU SEBOU — IF: 4510887
A3: PASSIF | B3: EXERCICE N | C3: EXERCICE N-1
A4: ▶ FINANCEMENT PERMANENT
A5: ▶ CAPITAUX PROPRES
A6: Capital social ou personnel
A7: Moins:actionnaires, capital souscrit non appelé
A8: capital appelé
A9: dont versé
A10: Prime d'émission, de fusion, d'apport
A11: Écarts de réévaluation
A12: Réserve légale
A13: Autres réserves
A14: Report à nouveau
A15: Résultat en instance d'affectation
A16: Résultat net de l'exercice
A17: Total des capitaux propres (A) | B17: =B6+B10+B11+B12+B13+B14+B15 | C17: =C6+C10+C11+C12+C13+C14+C15
A18: ▶ Capitaux propres assimilés (B)
A19: Subventions d'investissement
A20: Provisions réglementées
A21: Dettes de financement (C)
A22: Emprunts obligataires
A23: Autres dettes de financement
A24: Provisions durables pour risques et charges (D)
A25: Provisions pour risques
A26: Provisions pour charges
A27: Écarts de conversion - passif (E)
A28: Augmentation des créances immobilisées
A29: Diminution des dettes de financement
A30: TOTAL I (A+B+C+D+E) PASSIF | B30: =B16+B18+B19+B20+B23+B26 | C30: =C16+C18+C19+C20+C23+C26
A31: ▶ PASSIF CIRCULANT
A32: ▶ Dettes du passif circulant (F)
A33: Fournisseurs et comptes rattachés
A34: Clients créditeurs, avances et acomptes
A35: Personnel
A36: Organismes sociaux
A37: État
A38: Comptes d'associés
A39: Autres créanciers
A40: Comptes de régularisation passif
...

Sheet 4 - CPC
A1: COMPTE DE PRODUITS ET CHARGES | Du 01/01/2017 au 31/12/2017
A2: AGENCE DU BASSIN HYDRAULIQUE DU SEBOU — Hors Taxes
A3: DÉSIGNATION | B3: Propres à l'exercice N | C3: Exercices précédents | D3: TOTAL N | E3: TOTAL N-1
A4: ▶ PRODUITS D'EXPLOITATION
A5: Ventes de marchandises (en l'état) | D5: =B5+C5
A6: Ventes de biens et services produits | D6: =B6+C6
A7: Chiffre d'affaires | B7: =B6+B5 | C7: =C6+C5 | D7: =D6+D5 | E7: =E6+E5
A8: Variation de stocks de produits | D8: =B8+C8
A9: Immobilisations produites par l'entreprise | D9: =B9+C9
A10: Subventions d'exploitation | D10: =B10+C10
A11: Autres produits d'exploitation | D11: =B11+C11
A12: Reprises d'exploitation : transferts de charges | D12: =B12+C12
A13: TOTAL I - PRODUITS D'EXPLOITATION | B13: =B12+B11+B10+B9+B8+B7 | C13: =C12+C11+C10+C9+C8+C7 | D13: =D12+D11+D10+D9+D8+D7 | E13: =E12+E11+E10+E9+E8+E7
A14: ▶ CHARGES D'EXPLOITATION
A15: Achats revendus de marchandises | D15: =B15+C15
A16: Achats consommés de matières et fournitures | D16: =B16+C16
A17: Autres charges externes | D17: =B17+C17
A18: Impôts et taxes | D18: =B18+C18
A19: Charges de personnel | D19: =B19+C19
A20: Autres charges d'exploitation | D20: =B20+C20
A21: Dotations d'exploitation | D21: =B21+C21
A22: TOTAL II - CHARGES D'EXPLOITATION | B22: =B15+B16+B17+B18+B19+B20+B21 | C22: =C15+C16+C17+C18+C19+C20+C21 | D22: =D15+D16+D17+D18+D19+D20+D21 | E22: =E15+E16+E17+E18+E19+E20+E21
A23: RÉSULTAT D'EXPLOITATION (I-II) | B23: =B13-B22 | C23: =C13-C22 | D23: =D13-D22 | E23: =E13-E22
A24: ▶ PRODUITS FINANCIERS
A25: Produits des titres de participation | D25: =B25+C25
A26: Gains de change | D26: =B26+C26
A27: Intérêts et autres produits financiers | D27: =B27+C27
A28: Reprises financières : transferts de charges | D28: =B28+C28
A29: TOTAL IV - PRODUITS FINANCIERS | B29: =B25+B26+B27+B28 | C29: =C25+C26+C27+C28 | D29: =D25+D26+D27+D28 | E29: =E25+E26+E27+E28
A30: ▶ CHARGES FINANCIÈRES
A31: Charges d'intérêts | D31: =B31+C31
A32: Pertes de change | D32: =B32+C32
A33: Autres charges financières | D33: =B33+C33
A34: Dotations financières | D34: =B34+C34
A35: TOTAL V - CHARGES FINANCIÈRES | B35: =B31+B32+B33+B34 | C35: =C31+C32+C33+C34 | D35: =D31+D32+D33+D34 | E35: =E31+E32+E33+E34
A36: RÉSULTAT FINANCIER (IV-V) | B36: =B29-B35 | C36: =C29-C35 | D36: =D29-D35 | E36: =E29-E35
A37: RÉSULTAT COURANT (III+VI) | B37: =B23+B36 | C37: =C23+C36 | D37: =D23+D36 | E37: =E23+E36
A38: ▶ PRODUITS NON COURANTS
A39: Produits des cessions d'immobilisations | D39: =B39+C39
A40: Subventions d'équilibre | D40: =B40+C40
...

Sheet 5 - Tableau de Bord
A1: TABLEAU DE BORD — SYNTHÈSE FINANCIÈRE
A2: AGENCE DU BASSIN HYDRAULIQUE DU SEBOU
A3: INDICATEUR | B3: EXERCICE N | C3: EXERCICE N-1 | D3: Δ (N vs N-1) | E3: Unité
A4: 📈 COMPTE DE RÉSULTATS
A5: Chiffre d'affaires | B5: ='4 - CPC'!D7 | C5: ='4 - CPC'!E7 | D5: =B5-C5 | E5: MAD
A6: Produits d'exploitation | B6: ='4 - CPC'!D13 | C6: ='4 - CPC'!E13 | D6: =B6-C6 | E6: MAD
A7: Charges d'exploitation | B7: ='4 - CPC'!D22 | C7: ='4 - CPC'!E22 | D7: =B7-C7 | E7: MAD
A8: Résultat d'exploitation | B8: ='4 - CPC'!D23 | C8: ='4 - CPC'!E23 | D8: =B8-C8 | E8: MAD
A9: Résultat financier | B9: ='4 - CPC'!D36 | C9: ='4 - CPC'!E36 | D9: =B9-C9 | E9: MAD
A10: Résultat courant | B10: ='4 - CPC'!D37 | C10: ='4 - CPC'!E37 | D10: =B10-C10 | E10: MAD
A11: Résultat net de l'exercice | B11: ='4 - CPC'!D54 | C11: ='4 - CPC'!E54 | D11: =B11-C11 | E11: MAD
A12: 📊 BILAN — ACTIF
A13: Actif immobilisé net | B13: ='2 - Bilan Actif'!D30 | C13: ='2 - Bilan Actif'!E30 | D13: =B13-C13 | E13: MAD
A14: Actif circulant net | B14: ='2 - Bilan Actif'!D48 | C14: ='2 - Bilan Actif'!E48 | D14: =B14-C14 | E14: MAD
A15: Trésorerie actif | B15: ='2 - Bilan Actif'!D53 | C15: ='2 - Bilan Actif'!E53 | D15: =B15-C15 | E15: MAD
A16: TOTAL GÉNÉRAL ACTIF | B16: ='2 - Bilan Actif'!D54 | C16: ='2 - Bilan Actif'!E54 | D16: =B16-C16 | E16: MAD
A17: 📊 BILAN — PASSIF
A18: Capitaux propres | B18: ='3 - Bilan Passif'!B16 | C18: ='3 - Bilan Passif'!C16 | D18: =B18-C18 | E18: MAD
A19: Subventions d'investissement | B19: ='3 - Bilan Passif'!B18 | C19: ='3 - Bilan Passif'!C18 | D19: =B19-C19 | E19: MAD
A20: Financement permanent | B20: ='3 - Bilan Passif'!B29 | C20: ='3 - Bilan Passif'!C29 | D20: =B20-C20 | E20: MAD
A21: TOTAL GÉNÉRAL PASSIF | B21: ='3 - Bilan Passif'!B48 | C21: ='3 - Bilan Passif'!C48 | D21: =B21-C21 | E21: MAD
